{
  "comments": [
    {
      "unresolved": true,
      "key": {
        "uuid": "14812253_b16d0dbb",
        "filename": "src/main.cpp",
        "patchSetId": 6
      },
      "lineNbr": 159,
      "author": {
        "id": 1001184
      },
      "writtenOn": "2025-06-10T05:35:27Z",
      "side": 1,
      "message": "nit: this seems to be the same as above std::exception section except for one message. Perhaps it makes sense to put them in a function to avoid duplicate code",
      "range": {
        "startLine": 137,
        "startChar": 0,
        "endLine": 159,
        "endChar": 9
      },
      "revId": "291f7d88b77879228677e347f35bc36becad80b7",
      "serverId": "adbd0a64-1f21-4d83-b585-671fe73cb6e4"
    }
  ]
}